<?xml version="1.0"?>
<robot name="go2w_placeholder">
  <material name="black">
    <color rgba="0.08 0.08 0.08 1.0"/>
  </material>

  <link name="base_footprint"/>

  <link name="base_link">
    <visual>
      <geometry>
        <box size="0.58 0.34 0.12"/>
      </geometry>
      <material name="graphite">
        <color rgba="0.20 0.22 0.25 1.0"/>
      </material>
    </visual>
    <collision>
      <geometry>
        <box size="0.58 0.34 0.12"/>
      </geometry>
    </collision>
    <inertial>
      <mass value="22.0"/>
      <origin xyz="0 0 0" rpy="0 0 0"/>
      <inertia ixx="0.35" ixy="0.0" ixz="0.0" iyy="0.90" iyz="0.0" izz="1.05"/>
    </inertial>
  </link>

  <joint name="base_footprint_joint" type="fixed">
    <parent link="base_footprint"/>
    <child link="base_link"/>
    <origin xyz="0 0 0.12" rpy="0 0 0"/>
  </joint>

  <link name="sensor_mount_link">
    <visual>
      <geometry>
        <box size="0.10 0.08 0.06"/>
      </geometry>
      <material name="silver">
        <color rgba="0.75 0.76 0.78 1.0"/>
      </material>
    </visual>
    <collision>
      <geometry>
        <box size="0.10 0.08 0.06"/>
      </geometry>
    </collision>
    <inertial>
      <mass value="0.5"/>
      <origin xyz="0 0 0" rpy="0 0 0"/>
      <inertia ixx="0.002" ixy="0.0" ixz="0.0" iyy="0.003" iyz="0.0" izz="0.004"/>
    </inertial>
  </link>

  <joint name="sensor_mount_joint" type="fixed">
    <parent link="base_link"/>
    <child link="sensor_mount_link"/>
    <origin xyz="0.12 0 0.11" rpy="0 0 0"/>
  </joint>

  <link name="lidar_link">
    <visual>
      <geometry>
        <cylinder radius="0.035" length="0.05"/>
      </geometry>
      <material name="black"/>
    </visual>
    <collision>
      <geometry>
        <cylinder radius="0.035" length="0.05"/>
      </geometry>
    </collision>
    <inertial>
      <mass value="0.2"/>
      <origin xyz="0 0 0" rpy="0 0 0"/>
      <inertia ixx="0.0002" ixy="0.0" ixz="0.0" iyy="0.0002" iyz="0.0" izz="0.0002"/>
    </inertial>
  </link>

  <joint name="lidar_joint" type="fixed">
    <parent link="sensor_mount_link"/>
    <child link="lidar_link"/>
    <origin xyz="0.02 0 0.055" rpy="0 0 0"/>
  </joint>

  <link name="imu_link">
    <visual>
      <geometry>
        <box size="0.03 0.03 0.02"/>
      </geometry>
      <material name="silver"/>
    </visual>
    <collision>
      <geometry>
        <box size="0.03 0.03 0.02"/>
      </geometry>
    </collision>
    <inertial>
      <mass value="0.05"/>
      <origin xyz="0 0 0" rpy="0 0 0"/>
      <inertia ixx="0.00002" ixy="0.0" ixz="0.0" iyy="0.00002" iyz="0.0" izz="0.00002"/>
    </inertial>
  </link>

  <joint name="imu_joint" type="fixed">
    <parent link="sensor_mount_link"/>
    <child link="imu_link"/>
    <origin xyz="-0.02 0 0.0" rpy="0 0 0"/>
  </joint>

  <link name="left_wheel_link">
    <visual>
      <origin xyz="0 0 0" rpy="1.57079632679 0 0"/>
      <geometry>
        <cylinder radius="0.10" length="0.05"/>
      </geometry>
      <material name="black">
        <color rgba="0.08 0.08 0.08 1.0"/>
      </material>
    </visual>
    <collision>
      <origin xyz="0 0 0" rpy="1.57079632679 0 0"/>
      <geometry>
        <cylinder radius="0.10" length="0.05"/>
      </geometry>
    </collision>
    <inertial>
      <mass value="1.0"/>
      <origin xyz="0 0 0" rpy="0 0 0"/>
      <inertia ixx="0.005" ixy="0.0" ixz="0.0" iyy="0.003" iyz="0.0" izz="0.005"/>
    </inertial>
  </link>

  <joint name="left_wheel_joint" type="continuous">
    <parent link="base_link"/>
    <child link="left_wheel_link"/>
    <origin xyz="0.0 0.20 -0.04" rpy="0 0 0"/>
    <axis xyz="0 1 0"/>
    <limit effort="30.0" velocity="20.0"/>
  </joint>

  <link name="right_wheel_link">
    <visual>
      <origin xyz="0 0 0" rpy="1.57079632679 0 0"/>
      <geometry>
        <cylinder radius="0.10" length="0.05"/>
      </geometry>
      <material name="black"/>
    </visual>
    <collision>
      <origin xyz="0 0 0" rpy="1.57079632679 0 0"/>
      <geometry>
        <cylinder radius="0.10" length="0.05"/>
      </geometry>
    </collision>
    <inertial>
      <mass value="1.0"/>
      <origin xyz="0 0 0" rpy="0 0 0"/>
      <inertia ixx="0.005" ixy="0.0" ixz="0.0" iyy="0.003" iyz="0.0" izz="0.005"/>
    </inertial>
  </link>

  <joint name="right_wheel_joint" type="continuous">
    <parent link="base_link"/>
    <child link="right_wheel_link"/>
    <origin xyz="0.0 -0.20 -0.04" rpy="0 0 0"/>
    <axis xyz="0 1 0"/>
    <limit effort="30.0" velocity="20.0"/>
  </joint>

  <link name="front_support_link">
    <visual>
      <origin xyz="0 0 0" rpy="0 0 0"/>
      <geometry>
        <sphere radius="0.03"/>
      </geometry>
      <material name="silver"/>
    </visual>
    <collision>
      <origin xyz="0 0 0" rpy="0 0 0"/>
      <geometry>
        <sphere radius="0.03"/>
      </geometry>
    </collision>
    <inertial>
      <mass value="0.3"/>
      <origin xyz="0 0 0" rpy="0 0 0"/>
      <inertia ixx="0.0002" ixy="0.0" ixz="0.0" iyy="0.0002" iyz="0.0" izz="0.0002"/>
    </inertial>
  </link>

  <joint name="front_support_joint" type="fixed">
    <parent link="base_link"/>
    <child link="front_support_link"/>
    <origin xyz="0.20 0.0 -0.11" rpy="0 0 0"/>
  </joint>

  <link name="rear_support_link">
    <visual>
      <origin xyz="0 0 0" rpy="0 0 0"/>
      <geometry>
        <sphere radius="0.03"/>
      </geometry>
      <material name="silver"/>
    </visual>
    <collision>
      <origin xyz="0 0 0" rpy="0 0 0"/>
      <geometry>
        <sphere radius="0.03"/>
      </geometry>
    </collision>
    <inertial>
      <mass value="0.3"/>
      <origin xyz="0 0 0" rpy="0 0 0"/>
      <inertia ixx="0.0002" ixy="0.0" ixz="0.0" iyy="0.0002" iyz="0.0" izz="0.0002"/>
    </inertial>
  </link>

  <joint name="rear_support_joint" type="fixed">
    <parent link="base_link"/>
    <child link="rear_support_link"/>
    <origin xyz="-0.20 0.0 -0.11" rpy="0 0 0"/>
  </joint>

  <ros2_control name="go2w_gz_ros2_control" type="system">
    <hardware>
      <plugin>gz_ros2_control/GazeboSimSystem</plugin>
    </hardware>

    <joint name="left_wheel_joint">
      <command_interface name="velocity">
        <param name="min">-10.0</param>
        <param name="max">10.0</param>
      </command_interface>
      <state_interface name="position"/>
      <state_interface name="velocity"/>
    </joint>
    <joint name="right_wheel_joint">
      <command_interface name="velocity">
        <param name="min">-10.0</param>
        <param name="max">10.0</param>
      </command_interface>
      <state_interface name="position"/>
      <state_interface name="velocity"/>
    </joint>
  </ros2_control>

  <gazebo>
    <plugin filename="gz_ros2_control-system" name="gz_ros2_control::GazeboSimROS2ControlPlugin">
      <robot_param>robot_description</robot_param>
      <robot_param_node>robot_state_publisher</robot_param_node>
      <parameters>__GO2W_CONTROLLERS_YAML__</parameters>
      <controller_manager_name>controller_manager</controller_manager_name>
      <ros>
        <remapping>diff_drive_controller/cmd_vel_unstamped:=/cmd_vel</remapping>
      </ros>
    </plugin>
  </gazebo>

  <gazebo reference="left_wheel_link">
    <mu1>1.2</mu1>
    <mu2>1.2</mu2>
  </gazebo>
  <gazebo reference="right_wheel_link">
    <mu1>1.2</mu1>
    <mu2>1.2</mu2>
  </gazebo>
  <gazebo reference="lidar_link">
    <sensor name="lidar_sensor" type="gpu_lidar">
      <pose>0 0 0 0 0 0</pose>
      <topic>/lidar</topic>
      <always_on>1</always_on>
      <update_rate>10</update_rate>
      <visualize>false</visualize>
      <lidar>
        <scan>
          <horizontal>
            <samples>360</samples>
            <resolution>1</resolution>
            <min_angle>-3.14159265359</min_angle>
            <max_angle>3.14159265359</max_angle>
          </horizontal>
          <vertical>
            <samples>16</samples>
            <resolution>1</resolution>
            <min_angle>-0.26179938779</min_angle>
            <max_angle>0.26179938779</max_angle>
          </vertical>
        </scan>
        <range>
          <min>0.10</min>
          <max>20.0</max>
          <resolution>0.01</resolution>
        </range>
      </lidar>
    </sensor>
  </gazebo>
  <gazebo reference="imu_link">
    <sensor name="imu_sensor" type="imu">
      <pose>0 0 0 0 0 0</pose>
      <topic>/imu</topic>
      <always_on>1</always_on>
      <update_rate>100</update_rate>
      <visualize>false</visualize>
    </sensor>
  </gazebo>
</robot>
